<?xml version="1.0" ?>
<robot name="stea" xmlns:xacro="http://www.ros.org/wiki/xacro">

<xacro:include filename="$(find stea_description)/urdf/materials.xacro" />
<xacro:include filename="$(find stea_description)/urdf/stea.trans" />
<xacro:include filename="$(find stea_description)/urdf/stea.gazebo" />
<link name="base_link">
  <inertial>
    <origin xyz="0.43700000000022443 0.3644999999999999 0.005" rpy="0 0 0"/>
    <mass value="7.323742327294597"/>
    <inertia ixx="0.446477" iyy="0.446477" izz="0.892833" ixy="-0.0" iyz="0.0" ixz="0.0"/>
  </inertial>
  <visual>
    <origin xyz="0 0 0" rpy="0 0 0"/>
    <geometry>
      <mesh filename="file://$(find stea_description)/meshes/base_link.stl" scale="0.001 0.001 0.001"/>
    </geometry>
    <material name="silver"/>
  </visual>
  <collision>
    <origin xyz="0 0 0" rpy="0 0 0"/>
    <geometry>
      <mesh filename="file://$(find stea_description)/meshes/base_link.stl" scale="0.001 0.001 0.001"/>
    </geometry>
  </collision>
</link>

<link name="Part2_1">
  <inertial>
    <origin xyz="-0.4369999999999999 -0.34450000000000003 0.0099999999999913" rpy="0 0 0"/>
    <mass value="0.08260706787638175"/>
    <inertia ixx="4.7e-05" iyy="7e-05" izz="0.000112" ixy="-4e-06" iyz="0.0" ixz="0.0"/>
  </inertial>
  <visual>
    <origin xyz="-0.5195 -0.3545 -0.0" rpy="0 0 0"/>
    <geometry>
      <mesh filename="file://$(find stea_description)/meshes/Part2_1.stl" scale="0.001 0.001 0.001"/>
    </geometry>
    <material name="silver"/>
  </visual>
  <collision>
    <origin xyz="-0.5195 -0.3545 -0.0" rpy="0 0 0"/>
    <geometry>
      <mesh filename="file://$(find stea_description)/meshes/Part2_1.stl" scale="0.001 0.001 0.001"/>
    </geometry>
  </collision>
</link>

<link name="Part4_1">
  <inertial>
    <origin xyz="-0.43699999999999917 1.073499999999999 0.0099999999999913" rpy="0 0 0"/>
    <mass value="0.08260706787638175"/>
    <inertia ixx="5.7e-05" iyy="6e-05" izz="0.000112" ixy="1.2e-05" iyz="-0.0" ixz="0.0"/>
  </inertial>
  <visual>
    <origin xyz="-0.5195 0.3545 -0.0" rpy="0 0 0"/>
    <geometry>
      <mesh filename="file://$(find stea_description)/meshes/Part4_1.stl" scale="0.001 0.001 0.001"/>
    </geometry>
    <material name="silver"/>
  </visual>
  <collision>
    <origin xyz="-0.5195 0.3545 -0.0" rpy="0 0 0"/>
    <geometry>
      <mesh filename="file://$(find stea_description)/meshes/Part4_1.stl" scale="0.001 0.001 0.001"/>
    </geometry>
  </collision>
</link>

<link name="Part5_1">
  <inertial>
    <origin xyz="-0.43699999999999983 -0.3445 0.0099999999999913" rpy="0 0 0"/>
    <mass value="0.08260706787638175"/>
    <inertia ixx="4.6e-05" iyy="7.1e-05" izz="0.000112" ixy="0.0" iyz="-0.0" ixz="0.0"/>
  </inertial>
  <visual>
    <origin xyz="-1.2285 -0.3545 -0.0" rpy="0 0 0"/>
    <geometry>
      <mesh filename="file://$(find stea_description)/meshes/Part5_1.stl" scale="0.001 0.001 0.001"/>
    </geometry>
    <material name="silver"/>
  </visual>
  <collision>
    <origin xyz="-1.2285 -0.3545 -0.0" rpy="0 0 0"/>
    <geometry>
      <mesh filename="file://$(find stea_description)/meshes/Part5_1.stl" scale="0.001 0.001 0.001"/>
    </geometry>
  </collision>
</link>

<link name="Part3_1">
  <inertial>
    <origin xyz="-0.43699999999999983 1.0735000000000001 0.0099999999999913" rpy="0 0 0"/>
    <mass value="0.08260706787638175"/>
    <inertia ixx="4.6e-05" iyy="7.1e-05" izz="0.000112" ixy="0.0" iyz="0.0" ixz="0.0"/>
  </inertial>
  <visual>
    <origin xyz="-1.2285 0.3545 -0.0" rpy="0 0 0"/>
    <geometry>
      <mesh filename="file://$(find stea_description)/meshes/Part3_1.stl" scale="0.001 0.001 0.001"/>
    </geometry>
    <material name="silver"/>
  </visual>
  <collision>
    <origin xyz="-1.2285 0.3545 -0.0" rpy="0 0 0"/>
    <geometry>
      <mesh filename="file://$(find stea_description)/meshes/Part3_1.stl" scale="0.001 0.001 0.001"/>
    </geometry>
  </collision>
</link>

<link name="wheel_1">
  <inertial>
    <origin xyz="1.316280709068307e-06 -7.490295972384375e-06 -6.049883922550764e-06" rpy="0 0 0"/>
    <mass value="0.07051856513617272"/>
    <inertia ixx="5.6e-05" iyy="3.2e-05" izz="3.2e-05" ixy="4e-06" iyz="0.0" ixz="-0.0"/>
  </inertial>
  <visual>
    <origin xyz="-0.0825 -0.01 -0.01" rpy="0 0 0"/>
    <geometry>
      <mesh filename="file://$(find stea_description)/meshes/wheel_1.stl" scale="0.001 0.001 0.001"/>
    </geometry>
    <material name="silver"/>
  </visual>
  <collision>
    <origin xyz="-0.0825 -0.01 -0.01" rpy="0 0 0"/>
    <geometry>
      <mesh filename="file://$(find stea_description)/meshes/wheel_1.stl" scale="0.001 0.001 0.001"/>
    </geometry>
  </collision>
</link>

<link name="wheel3_1">
  <inertial>
    <origin xyz="6.35530171250176e-06 7.351759263030111e-06 2.611573630961761e-11" rpy="0 0 0"/>
    <mass value="0.07051856513617272"/>
    <inertia ixx="4.6e-05" iyy="4.2e-05" izz="3.2e-05" ixy="-1.2e-05" iyz="0.0" ixz="0.0"/>
  </inertial>
  <visual>
    <origin xyz="-0.0825 -0.719 -0.01" rpy="0 0 0"/>
    <geometry>
      <mesh filename="file://$(find stea_description)/meshes/wheel3_1.stl" scale="0.001 0.001 0.001"/>
    </geometry>
    <material name="silver"/>
  </visual>
  <collision>
    <origin xyz="-0.0825 -0.719 -0.01" rpy="0 0 0"/>
    <geometry>
      <mesh filename="file://$(find stea_description)/meshes/wheel3_1.stl" scale="0.001 0.001 0.001"/>
    </geometry>
  </collision>
</link>

<link name="wheel2_1">
  <inertial>
    <origin xyz="-1.4845569218380206e-11 9.717933119990363e-06 2.611573630961761e-11" rpy="0 0 0"/>
    <mass value="0.07051856513617272"/>
    <inertia ixx="5.7e-05" iyy="3.2e-05" izz="3.2e-05" ixy="-0.0" iyz="0.0" ixz="0.0"/>
  </inertial>
  <visual>
    <origin xyz="-0.7915 -0.719 -0.01" rpy="0 0 0"/>
    <geometry>
      <mesh filename="file://$(find stea_description)/meshes/wheel2_1.stl" scale="0.001 0.001 0.001"/>
    </geometry>
    <material name="silver"/>
  </visual>
  <collision>
    <origin xyz="-0.7915 -0.719 -0.01" rpy="0 0 0"/>
    <geometry>
      <mesh filename="file://$(find stea_description)/meshes/wheel2_1.stl" scale="0.001 0.001 0.001"/>
    </geometry>
  </collision>
</link>

<link name="wheel4_1">
  <inertial>
    <origin xyz="-1.4845569218380206e-11 9.717933119938321e-06 2.611573630961761e-11" rpy="0 0 0"/>
    <mass value="0.07051856513617272"/>
    <inertia ixx="5.7e-05" iyy="3.2e-05" izz="3.2e-05" ixy="-0.0" iyz="0.0" ixz="0.0"/>
  </inertial>
  <visual>
    <origin xyz="-0.7915 -0.01 -0.01" rpy="0 0 0"/>
    <geometry>
      <mesh filename="file://$(find stea_description)/meshes/wheel4_1.stl" scale="0.001 0.001 0.001"/>
    </geometry>
    <material name="silver"/>
  </visual>
  <collision>
    <origin xyz="-0.7915 -0.01 -0.01" rpy="0 0 0"/>
    <geometry>
      <mesh filename="file://$(find stea_description)/meshes/wheel4_1.stl" scale="0.001 0.001 0.001"/>
    </geometry>
  </collision>
</link>

<joint name="Rev1" type="continuous">
  <origin xyz="0.5195 0.3545 0.0" rpy="0 0 0"/>
  <parent link="base_link"/>
  <child link="Part2_1"/>
  <axis xyz="-0.0 -0.0 -1.0"/>
</joint>

<joint name="Rev2" type="continuous">
  <origin xyz="0.5195 -0.3545 0.0" rpy="0 0 0"/>
  <parent link="base_link"/>
  <child link="Part4_1"/>
  <axis xyz="-0.0 -0.0 -1.0"/>
</joint>

<joint name="Rev3" type="continuous">
  <origin xyz="1.2285 0.3545 0.0" rpy="0 0 0"/>
  <parent link="base_link"/>
  <child link="Part5_1"/>
  <axis xyz="-0.0 -0.0 -1.0"/>
</joint>

<joint name="Rev4" type="continuous">
  <origin xyz="1.2285 -0.3545 0.0" rpy="0 0 0"/>
  <parent link="base_link"/>
  <child link="Part3_1"/>
  <axis xyz="-0.0 -0.0 -1.0"/>
</joint>

<joint name="Rev5" type="continuous">
  <origin xyz="-0.437 -0.3445 0.01" rpy="0 0 0"/>
  <parent link="Part2_1"/>
  <child link="wheel_1"/>
  <axis xyz="0.984908 0.173081 -0.0"/>
</joint>

<joint name="Rev6" type="continuous">
  <origin xyz="-0.437 1.0735 0.01" rpy="0 0 0"/>
  <parent link="Part4_1"/>
  <child link="wheel3_1"/>
  <axis xyz="0.756514 -0.653978 0.0"/>
</joint>

<joint name="Rev7" type="continuous">
  <origin xyz="-0.437 1.0735 0.01" rpy="0 0 0"/>
  <parent link="Part3_1"/>
  <child link="wheel2_1"/>
  <axis xyz="1.0 -0.0 -0.0"/>
</joint>

<joint name="Rev8" type="continuous">
  <origin xyz="-0.437 -0.3445 0.01" rpy="0 0 0"/>
  <parent link="Part5_1"/>
  <child link="wheel4_1"/>
  <axis xyz="1.0 -0.0 0.0"/>
</joint>

</robot>
